package com.renomad.minum.utils;

import com.renomad.minum.state.Context;
import com.renomad.minum.logging.TestCanonicalLogger;
import com.renomad.minum.testing.TestFailureException;
import org.junit.AfterClass;
import org.junit.BeforeClass;
import org.junit.Test;

import java.util.concurrent.Future;

import static com.renomad.minum.testing.TestFramework.*;

public class ThrowingRunnableTests {

    private static Context context;
    private static TestCanonicalLogger logger;

    @BeforeClass
    public static void init() {
        context = buildTestingContext("unit_tests");
        logger = (TestCanonicalLogger) context.getLogger();
    }

    @AfterClass
    public static void cleanup() {
        shutdownTestingContext(context);
    }

    /**
     * Trying to handle exceptions well in a multi-threaded system is a matter
     * of compromises.  The purpose here is to at least have the opportunity to
     * log the exception.
     */
    @Test
    public void testThrowingRunnable() {
        String message = "testing throwingRunnableWrapper";
        Runnable runnable = ThrowingRunnable.throwingRunnableWrapper(() -> {
            throw new RuntimeException(message);
        }, logger);

        Future<?> result = context.getExecutorService().submit(runnable);

        assertThrows(TestFailureException.class, result::get);
        MyThread.sleep(50);
        String foundLog = logger.findFirstMessageThatContains(message, 6);
        assertTrue(foundLog.contains(message));
    }
}
